Workbook

Sheet 03_RAW_DATA
B1: 03 | RAW DATA — Elm Company (شركة علم) — Consolidated Financial Statements
B2: All figures in SAR '000 (thousand Saudi Riyals) unless otherwise noted. Source: audited consolidated FS (BDO Dr. Mohamed Al-Amri & Co.).
B3: FY2025 & FY2024 taken from the FY2025 report (FY2024 = restated comparatives); FY2023 taken from the FY2024 report comparatives (reclassified: R&D split out of cost of revenue/G&A). Blue = input from PDF, black = formula.
B6: SECTION A — INCOME STATEMENT
B7: Line Item | C7: FY2023 | D7: FY2024 | E7: FY2025 | F7: Notes
B8: Revenue | C8: 5898362.8 | D8: 7406794.4 | E8: 9464885 | F8: Note 5
B9: Cost of Revenue (COGS) | C9: 3566638.6 | D9: 4375702.5 | E9: 5787332.8 | F9: Note 6
B10: Gross Profit | C10: =C8-C9 -> 2331724.3 | D10: =D8-D9 -> 3031091.9 | E10: =E8-E9 -> 3677552.2
B11: Research & development | C11: 51585.026 | D11: 75532.533 | E11: 105377.71
B12: Selling & marketing | C12: 278660.07 | D12: 335606.45 | E12: 403362.64
B13: Expected credit losses | C13: 91770.357 | D13: 142748.6 | E13: 105710.34
B14: General & administrative | C14: 433233.56 | D14: 556569.81 | E14: 748519.57
B15: SG&A Expenses (incl. R&D and ECL) | C15: =SUM(C11:C14) -> 855249.01 | D15: =SUM(D11:D14) -> 1110457.4 | E15: =SUM(E11:E14) -> 1362970.3 | F15: Sum of the four opex lines above
B16: Depreciation & Amortization | C16: 119972.9 | D16: 198838.58 | E16: 254424.32
B17: Impairment of non-current assets | C17: 5918.692 | D17: 21343.476 | E17: 30210.394
B18: EBIT (Operating Income) | C18: =C10-C15-C16-C17 -> 1350583.7 | D18: =D10-D15-D16-D17 -> 1700452.4 | E18: =E10-E15-E16-E17 -> 2029947.2 | F18: Ties to 'Income from operations' in the PDF
B19: Interest Expense (finance costs) | C19: 5861.229 | D19: 28447.26 | E19: 105799.38 | F19: FY2025 up on new SAR 1.9bn long-term loan
B20: Murabaha deposit income | C20: 127856.09 | D20: 145475.64 | E20: 134684.76
B21: Share of results of associates / JV | C21: -11946.369 | D21: -1644.095 | E21: -4461.958
B22: Gain / (loss) on financial assets at FVTPL | C22: -15968.64 | D22: 34211.615 | E22: 23692.08
B23: Other income, net | C23: 28588.884 | D23: 103820.06 | E23: 57973.148
B24: Other Income (total non-operating) | C24: =SUM(C20:C23) -> 128529.96 | D24: =SUM(D20:D23) -> 281863.22 | E24: =SUM(E20:E23) -> 211888.03
B25: EBT (Income before Zakat) | C25: =C18-C19+C24 -> 1473252.4 | D25: =D18-D19+D24 -> 1953868.4 | E25: =E18-E19+E24 -> 2136035.9
B26: Zakat (income tax equivalent) | C26: 117057.65 | D26: 127019.91 | E26: 45710.979 | F26: Saudi entity — zakat, not income tax
B27: Net Income | C27: =C25-C26 -> 1356194.8 | D27: =D25-D26 -> 1826848.5 | E27: =E25-E26 -> 2090324.9
B28: Attributable to shareholders of the parent | C28: 1356230.8 | D28: 1826871.6 | E28: 2090353
B29: Attributable to non-controlling interests | C29: -36 | D29: -23.118 | E29: -28.111
B30: Check: Net income vs PDF (should be 0) | C30: =ROUND(C27-C28-C29,3) -> 0 | D30: =ROUND(D27-D28-D29,3) -> 0 | E30: =ROUND(E27-E28-E29,3) -> 0
B33: SECTION B — BALANCE SHEET (AT YEAR-END)
B34: Line Item | C34: FY2023 | D34: FY2024 | E34: FY2025 | F34: Notes
B35: Cash & Cash Equivalents | C35: 384394.61 | D35: 2250797.2 | E35: 1836371.7 | F35: Note 22
B36: Murabaha deposits | C36: 3056113.6 | D36: 1426071 | E36: 2306000 | F36: Short-term bank deposits
B37: Accounts Receivable | C37: 2322353.7 | D37: 2895222.8 | E37: 3606503.8 | F37: Trade receivables, Note 18
B38: Contract assets | C38: 847625.68 | D38: 641667.69 | E38: 1173197.3
B39: Inventory | C39: 0 | D39: 0 | E39: 0 | F39: Not reported by Elm
B40: Finance lease receivable – current | C40: 0 | D40: 21399.046 | E40: 27584.336
B41: Prepayments & other current assets | C41: 372877.13 | D41: 310748.05 | E41: 447281.09
B42: Other financial assets – current | C42: 18797.335 | D42: 480597.59 | E42: 404602.32
B43: Other Current Assets | C43: =SUM(C40:C42) -> 391674.47 | D43: =SUM(D40:D42) -> 812744.68 | E43: =SUM(E40:E42) -> 879467.75
B44: Total Current Assets | C44: =C35+C36+C37+C38+C39+C43 -> 7002162.1 | D44: =D35+D36+D37+D38+D39+D43 -> 8026503.3 | E44: =E35+E36+E37+E38+E39+E43 -> 9801540.5
...

Sheet 04_ASSUMPTIONS
B1: 04 | ASSUMPTIONS — Benchmarks & Constants
B2: Benchmarks are the industry ranges given in the case template (logistics & distribution). Elm is an IT / digital-services company, so treat them as reference only. Edit the blue cells to use a different peer set.
B4: Days in year | C4: 365
B6: Ratio | C6: Low | D6: High | E6: Unit
B7: Gross Margin | C7: 0.3 | D7: 0.33 | E7: %
B8: EBIT Margin | C8: 0.09 | D8: 0.11 | E8: %
B9: Net Profit Margin | C9: 0.06 | D9: 0.08 | E9: %
B10: Current Ratio | C10: 1.3 | D10: 1.6 | E10: x
B11: Debt-to-Equity | C11: 1 | D11: 1.3 | E11: x
B12: Inventory Turnover | C12: 8 | D12: 9 | E12: x
B13: DSO | C13: 50 | D13: 55 | E13: days

Sheet 05_ANALYSIS
A1: 05 | ANALYSIS — Ratio Suite (Build Every Formula Yourself)
A2: Yellow cells are yours to complete. Reference 03_RAW_DATA and 04_ASSUMPTIONS — do not hardcode results.
A4: SECTION 1 — PROFITABILITY RATIOS
A5: Ratio | B5: Definition (Guide) | C5: FY2023 | D5: FY2024 | E5: FY2025 | F5: vs. Industry Benchmark | G5: Explanation
A6: Gross Margin | B6: Gross Profit / Revenue | C6: ='03_RAW_DATA'!C10/'03_RAW_DATA'!C8 -> 0.3953172 | D6: ='03_RAW_DATA'!D10/'03_RAW_DATA'!D8 -> 0.40923127 | E6: ='03_RAW_DATA'!E10/'03_RAW_DATA'!E8 -> 0.38854695 | F6: =TEXT('04_ASSUMPTIONS'!$C$7*100,"0")&"–"&TEXT('04_ASSUMPTIONS'!$D$7*100,"0")&"%"&" → "&IF(NOT(ISNUMBER(E6)),"n/a (no inventory reported)",IF(AND(IF(C6<'04_ASSUMPTIONS'!$C$7,"below",IF(C6>'04_ASSUMPTIONS'!$D$7,"above","within"))=IF(D6<'04_ASSUMPTIONS'!$C$7,"below",IF(D6>'04_ASSUMPTIONS'!$D$7,"above","within")),IF(D6<'04_ASSUMPTIONS'!$C$7,"below",IF(D6>'04_ASSUMPTIONS'!$D$7,"above","within"))=IF(E6<'04_ASSUMPTIONS'!$C$7,"below",IF(E6>'04_ASSUMPTIONS'!$D$7,"above","within"))),IF(E6<'04_ASSUMPTIONS'!$C$7,"below",IF(E6>'04_ASSUMPTIONS'!$D$7,"above","within"))&" range throughout",IF(E6<'04_ASSUMPTIONS'!$C$7,"below",IF(E6>'04_ASSUMPTIONS'!$D$7,"above","within"))&" range by FY2025")&", "&IF(E6>C6,"improving",IF(E6<C6,"worsening","flat"))) -> 30–33% → above range throughout, worsening | G6: Elm keeps ~39–41 SAR of every 100 SAR of revenue after direct costs — typical of a software/digital-services model, so it sits well above the logistics range. The slight FY2025 dip means cost of revenue (+32%) grew faster than revenue (+28%).
A7: EBIT Margin | B7: EBIT / Revenue | C7: ='03_RAW_DATA'!C18/'03_RAW_DATA'!C8 -> 0.22897602 | D7: ='03_RAW_DATA'!D18/'03_RAW_DATA'!D8 -> 0.22958008 | E7: ='03_RAW_DATA'!E18/'03_RAW_DATA'!E8 -> 0.21447141 | F7: =TEXT('04_ASSUMPTIONS'!$C$8*100,"0")&"–"&TEXT('04_ASSUMPTIONS'!$D$8*100,"0")&"%"&" → "&IF(NOT(ISNUMBER(E7)),"n/a (no inventory reported)",IF(AND(IF(C7<'04_ASSUMPTIONS'!$C$8,"below",IF(C7>'04_ASSUMPTIONS'!$D$8,"above","within"))=IF(D7<'04_ASSUMPTIONS'!$C$8,"below",IF(D7>'04_ASSUMPTIONS'!$D$8,"above","within")),IF(D7<'04_ASSUMPTIONS'!$C$8,"below",IF(D7>'04_ASSUMPTIONS'!$D$8,"above","within"))=IF(E7<'04_ASSUMPTIONS'!$C$8,"below",IF(E7>'04_ASSUMPTIONS'!$D$8,"above","within"))),IF(E7<'04_ASSUMPTIONS'!$C$8,"below",IF(E7>'04_ASSUMPTIONS'!$D$8,"above","within"))&" range throughout",IF(E7<'04_ASSUMPTIONS'!$C$8,"below",IF(E7>'04_ASSUMPTIONS'!$D$8,"above","within"))&" range by FY2025")&", "&IF(E7>C7,"improving",IF(E7<C7,"worsening","flat"))) -> 9–11% → above range throughout, worsening | G7: Operating profit is a steady ~21–23% of revenue. FY2025 eased to 21.5% as G&A, depreciation (new assets and acquisition) and impairments rose faster than sales. Still roughly double the top of the benchmark.
A8: Net Profit Margin | B8: Net Income / Revenue | C8: ='03_RAW_DATA'!C27/'03_RAW_DATA'!C8 -> 0.22992732 | D8: ='03_RAW_DATA'!D27/'03_RAW_DATA'!D8 -> 0.24664495 | E8: ='03_RAW_DATA'!E27/'03_RAW_DATA'!E8 -> 0.22085053 | F8: =TEXT('04_ASSUMPTIONS'!$C$9*100,"0")&"–"&TEXT('04_ASSUMPTIONS'!$D$9*100,"0")&"%"&" → "&IF(NOT(ISNUMBER(E8)),"n/a (no inventory reported)",IF(AND(IF(C8<'04_ASSUMPTIONS'!$C$9,"below",IF(C8>'04_ASSUMPTIONS'!$D$9,"above","within"))=IF(D8<'04_ASSUMPTIONS'!$C$9,"below",IF(D8>'04_ASSUMPTIONS'!$D$9,"above","within")),IF(D8<'04_ASSUMPTIONS'!$C$9,"below",IF(D8>'04_ASSUMPTIONS'!$D$9,"above","within"))=IF(E8<'04_ASSUMPTIONS'!$C$9,"below",IF(E8>'04_ASSUMPTIONS'!$D$9,"above","within"))),IF(E8<'04_ASSUMPTIONS'!$C$9,"below",IF(E8>'04_ASSUMPTIONS'!$D$9,"above","within"))&" range throughout",IF(E8<'04_ASSUMPTIONS'!$C$9,"below",IF(E8>'04_ASSUMPTIONS'!$D$9,"above","within"))&" range by FY2025")&", "&IF(E8>C8,"improving",IF(E8<C8,"worsening","flat"))) -> 6–8% → above range throughout, worsening | G8: Net margin is higher than EBIT margin because murabaha deposit income and investment gains exceed finance costs, and zakat is low. FY2025 fell as interest on the new loan rose and deposit income declined.
A9: Return on Assets (ROA) | B9: Net Income / Total Assets | C9: ='03_RAW_DATA'!C27/'03_RAW_DATA'!C55 -> 0.16748909 | D9: ='03_RAW_DATA'!D27/'03_RAW_DATA'!D55 -> 0.19121184 | E9: ='03_RAW_DATA'!E27/'03_RAW_DATA'!E55 -> 0.17584982 | F9: — (no benchmark given) | G9: Each 100 SAR of assets earns ~17–19 SAR of profit. FY2025 dipped because total assets jumped 24% (new loan, acquisition, receivables) while profit grew 14%.
A10: Return on Equity (ROE) | B10: Net Income / Total Equity | C10: ='03_RAW_DATA'!C27/'03_RAW_DATA'!C79 -> 0.33950092 | D10: ='03_RAW_DATA'!D27/'03_RAW_DATA'!D79 -> 0.34512823 | E10: ='03_RAW_DATA'!E27/'03_RAW_DATA'!E79 -> 0.57722911 | F10: — (no benchmark given) | G10: The FY2025 jump to 57.7% is NOT better performance: equity fell from SAR 5.3bn to 3.6bn after a SAR 3.1bn common-control acquisition charged to retained earnings (plus SAR 661m dividends). Smaller denominator = higher ROE.
A13: SECTION 2 — LIQUIDITY RATIOS
A14: Ratio | B14: Definition (Guide) | C14: FY2023 | D14: FY2024 | E14: FY2025 | F14: vs. Industry Benchmark | G14: Explanation
A15: Current Ratio | B15: Total Current Assets / Total Current Liabilities | C15: ='03_RAW_DATA'!C44/'03_RAW_DATA'!C64 -> 1.9837497 | D15: ='03_RAW_DATA'!D44/'03_RAW_DATA'!D64 -> 2.365913 | E15: ='03_RAW_DATA'!E44/'03_RAW_DATA'!E64 -> 1.74853 | F15: =TEXT('04_ASSUMPTIONS'!$C$10,"0.0")&"–"&TEXT('04_ASSUMPTIONS'!$D$10,"0.0")&"x"&" → "&IF(NOT(ISNUMBER(E15)),"n/a (no inventory reported)",IF(AND(IF(C15<'04_ASSUMPTIONS'!$C$10,"below",IF(C15>'04_ASSUMPTIONS'!$D$10,"above","within"))=IF(D15<'04_ASSUMPTIONS'!$C$10,"below",IF(D15>'04_ASSUMPTIONS'!$D$10,"above","within")),IF(D15<'04_ASSUMPTIONS'!$C$10,"below",IF(D15>'04_ASSUMPTIONS'!$D$10,"above","within"))=IF(E15<'04_ASSUMPTIONS'!$C$10,"below",IF(E15>'04_ASSUMPTIONS'!$D$10,"above","within"))),IF(E15<'04_ASSUMPTIONS'!$C$10,"below",IF(E15>'04_ASSUMPTIONS'!$D$10,"above","within"))&" range throughout",IF(E15<'04_ASSUMPTIONS'!$C$10,"below",IF(E15>'04_ASSUMPTIONS'!$D$10,"above","within"))&" range by FY2025")&", "&IF(E15>C15,"improving",IF(E15<C15,"worsening","flat"))) -> 1.3–1.6x → above range throughout, worsening | G15: Short-term assets cover short-term liabilities 1.75–2.4 times — comfortable. The FY2025 decline reflects cash used for the acquisition and higher payables, contract liabilities and the current portion of the loan.
A16: Quick Ratio | B16: (Total Current Assets − Inventory − Contract Assets) / Total Current Liabilities | C16: =('03_RAW_DATA'!C44-'03_RAW_DATA'!C39-'03_RAW_DATA'!C38)/'03_RAW_DATA'!C64 -> 1.7436128 | D16: =('03_RAW_DATA'!D44-'03_RAW_DATA'!D39-'03_RAW_DATA'!D38)/'03_RAW_DATA'!D64 -> 2.1767733 | E16: =('03_RAW_DATA'!E44-'03_RAW_DATA'!E39-'03_RAW_DATA'!E38)/'03_RAW_DATA'!E64 -> 1.5392394 | F16: — (no benchmark given) | G16: Excludes inventory (none) and contract assets (unbilled revenue), which cannot be converted to cash until invoiced. Liquid assets still cover current liabilities ~1.5–2.2x. FY2025 falls as cash went to the acquisition while contract assets jumped 83% (SAR 0.64bn → 1.17bn), i.e. more work done but not yet billed.
A17: Cash Ratio | B17: (Cash & Equivalents + Murabaha Deposits) / Total Current Liabilities | C17: =('03_RAW_DATA'!C35+'03_RAW_DATA'!C36)/'03_RAW_DATA'!C64 -> 0.97471423 | D17: =('03_RAW_DATA'!D35+'03_RAW_DATA'!D36)/'03_RAW_DATA'!D64 -> 1.0838032 | E17: =('03_RAW_DATA'!E35+'03_RAW_DATA'!E36)/'03_RAW_DATA'!E64 -> 0.73897171 | F17: — (no benchmark given) | G17: Includes cash plus murabaha (Islamic term) deposits — the only deposit type on Elm's balance sheet. Cash and deposits alone covered all current liabilities in FY2023–FY2024 (~0.97x → 1.08x). FY2025 falls to ~0.74x because cash was used for the SAR 3.1bn acquisition and current liabilities grew 65%.
A20: SECTION 3 — LEVERAGE RATIOS
A21: Ratio | B21: Definition (Guide) | C21: FY2023 | D21: FY2024 | E21: FY2025 | F21: vs. Industry Benchmark | G21: Explanation
A22: Debt-to-Equity | B22: (Short-Term Debt + Long-Term Debt) / Total Equity | C22: =('03_RAW_DATA'!C58+'03_RAW_DATA'!C65)/'03_RAW_DATA'!C79 -> 0 | D22: =('03_RAW_DATA'!D58+'03_RAW_DATA'!D65)/'03_RAW_DATA'!D79 -> 0 | E22: =('03_RAW_DATA'!E58+'03_RAW_DATA'!E65)/'03_RAW_DATA'!E79 -> 0.54494331 | F22: =TEXT('04_ASSUMPTIONS'!$C$11,"0.0")&"–"&TEXT('04_ASSUMPTIONS'!$D$11,"0.0")&"x"&" → "&IF(NOT(ISNUMBER(E22)),"n/a (no inventory reported)",IF(AND(IF(C22<'04_ASSUMPTIONS'!$C$11,"below",IF(C22>'04_ASSUMPTIONS'!$D$11,"above","within"))=IF(D22<'04_ASSUMPTIONS'!$C$11,"below",IF(D22>'04_ASSUMPTIONS'!$D$11,"above","within")),IF(D22<'04_ASSUMPTIONS'!$C$11,"below",IF(D22>'04_ASSUMPTIONS'!$D$11,"above","within"))=IF(E22<'04_ASSUMPTIONS'!$C$11,"below",IF(E22>'04_ASSUMPTIONS'!$D$11,"above","within"))),IF(E22<'04_ASSUMPTIONS'!$C$11,"below",IF(E22>'04_ASSUMPTIONS'!$D$11,"above","within"))&" range throughout",IF(E22<'04_ASSUMPTIONS'!$C$11,"below",IF(E22>'04_ASSUMPTIONS'!$D$11,"above","within"))&" range by FY2025")&", "&IF(E22>C22,"rising",IF(E22<C22,"falling","flat"))) -> 1.0–1.3x → below range throughout, rising | G22: Elm had no bank debt in FY2023–FY2024. In FY2025 it drew SAR 1.9bn to fund the acquisition, taking D/E to 0.54x — still below the range, so leverage is moderate. Lease liabilities are excluded per the guide.
A23: Debt-to-Assets | B23: Total Liabilities / Total Assets | C23: ='03_RAW_DATA'!C70/'03_RAW_DATA'!C55 -> 0.50666087 | D23: ='03_RAW_DATA'!D70/'03_RAW_DATA'!D55 -> 0.44596869 | E23: ='03_RAW_DATA'!E70/'03_RAW_DATA'!E55 -> 0.69535524 | F23: — (no benchmark given) | G23: Liabilities fund ~45–51% of assets until FY2025, when the new loan and lower equity push it to ~70%. Much of the liability base is non-interest-bearing (payables, contract liabilities).
A24: Interest Coverage | B24: EBIT / Interest Expense | C24: ='03_RAW_DATA'!C18/'03_RAW_DATA'!C19 -> 230.4267 | D24: ='03_RAW_DATA'!D18/'03_RAW_DATA'!D19 -> 59.775614 | E24: ='03_RAW_DATA'!E18/'03_RAW_DATA'!E19 -> 19.186759 | F24: — (no benchmark given) | G24: EBIT covers interest 19x even in FY2025 — very safe. The steep fall from 230x reflects finance costs rising from SAR 6m to SAR 106m as the company started borrowing.
A27: SECTION 4 — EFFICIENCY RATIOS
A28: Ratio | B28: Definition (Guide) | C28: FY2023 | D28: FY2024 | E28: FY2025 | F28: vs. Industry Benchmark | G28: Explanation
A29: Asset Turnover | B29: Revenue / Total Assets | C29: ='03_RAW_DATA'!C8/'03_RAW_DATA'!C55 -> 0.72844361 | D29: ='03_RAW_DATA'!D8/'03_RAW_DATA'!D55 -> 0.77525139 | E29: ='03_RAW_DATA'!E8/'03_RAW_DATA'!E55 -> 0.79623907 | G29: Elm generates ~0.73–0.80 SAR of revenue per SAR of assets. Low vs. an asset-heavy distributor because the balance sheet carries large cash, deposits and receivables; slowly improving.
A30: Inventory Turnover | B30: COGS / Inventory | C30: =IF('03_RAW_DATA'!C39=0,"n/a",'03_RAW_DATA'!C9/'03_RAW_DATA'!C39) -> n/a | D30: =IF('03_RAW_DATA'!D39=0,"n/a",'03_RAW_DATA'!D9/'03_RAW_DATA'!D39) -> n/a | E30: =IF('03_RAW_DATA'!E39=0,"n/a",'03_RAW_DATA'!E9/'03_RAW_DATA'!E39) -> n/a | F30: =TEXT('04_ASSUMPTIONS'!$C$12,"0.0")&"–"&TEXT('04_ASSUMPTIONS'!$D$12,"0.0")&"x"&" → "&IF(NOT(ISNUMBER(E30)),"n/a (no inventory reported)",IF(AND(IF(C30<'04_ASSUMPTIONS'!$C$12,"below",IF(C30>'04_ASSUMPTIONS'!$D$12,"above","within"))=IF(D30<'04_ASSUMPTIONS'!$C$12,"below",IF(D30>'04_ASSUMPTIONS'!$D$12,"above","within")),IF(D30<'04_ASSUMPTIONS'!$C$12,"below",IF(D30>'04_ASSUMPTIONS'!$D$12,"above","within"))=IF(E30<'04_ASSUMPTIONS'!$C$12,"below",IF(E30>'04_ASSUMPTIONS'!$D$12,"above","within"))),IF(E30<'04_ASSUMPTIONS'!$C$12,"below",IF(E30>'04_ASSUMPTIONS'!$D$12,"above","within"))&" range throughout",IF(E30<'04_ASSUMPTIONS'!$C$12,"below",IF(E30>'04_ASSUMPTIONS'!$D$12,"above","within"))&" range by FY2025")&", "&IF(E30>C30,"improving",IF(E30<C30,"worsening","flat"))) -> 8.0–9.0x → n/a (no inventory reported) | G30: Not applicable — Elm is a services/technology company and reports no inventory.
A31: Receivables Turnover | B31: Revenue / Accounts Receivable | C31: ='03_RAW_DATA'!C8/'03_RAW_DATA'!C37 -> 2.5398211 | D31: ='03_RAW_DATA'!D8/'03_RAW_DATA'!D37 -> 2.5582813 | E31: ='03_RAW_DATA'!E8/'03_RAW_DATA'!E37 -> 2.6243935 | G31: Receivables are collected ~2.5–2.6 times a year — slow, reflecting a customer base dominated by government entities with long payment cycles. Slight improvement each year.
A32: Days Sales Outstanding (DSO) | B32: 365 / Receivables Turnover | C32: ='04_ASSUMPTIONS'!$C$4/('03_RAW_DATA'!C8/'03_RAW_DATA'!C37) -> 143.71091 | D32: ='04_ASSUMPTIONS'!$C$4/('03_RAW_DATA'!D8/'03_RAW_DATA'!D37) -> 142.67391 | E32: ='04_ASSUMPTIONS'!$C$4/('03_RAW_DATA'!E8/'03_RAW_DATA'!E37) -> 139.07975 | F32: =TEXT('04_ASSUMPTIONS'!$C$13,"0")&"–"&TEXT('04_ASSUMPTIONS'!$D$13,"0")&" days"&" → "&IF(NOT(ISNUMBER(E32)),"n/a (no inventory reported)",IF(AND(IF(C32<'04_ASSUMPTIONS'!$C$13,"below",IF(C32>'04_ASSUMPTIONS'!$D$13,"above","within"))=IF(D32<'04_ASSUMPTIONS'!$C$13,"below",IF(D32>'04_ASSUMPTIONS'!$D$13,"above","within")),IF(D32<'04_ASSUMPTIONS'!$C$13,"below",IF(D32>'04_ASSUMPTIONS'!$D$13,"above","within"))=IF(E32<'04_ASSUMPTIONS'!$C$13,"below",IF(E32>'04_ASSUMPTIONS'!$D$13,"above","within"))),IF(E32<'04_ASSUMPTIONS'!$C$13,"below",IF(E32>'04_ASSUMPTIONS'!$D$13,"above","within"))&" range throughout",IF(E32<'04_ASSUMPTIONS'!$C$13,"below",IF(E32>'04_ASSUMPTIONS'!$D$13,"above","within"))&" range by FY2025")&", "&IF(E32>C32,"worsening",IF(E32<C32,"improving","flat"))) -> 50–55 days → above range throughout, improving | G32: It takes ~140 days on average to collect from customers — about 2.5x the benchmark. This is the main working-capital risk, though it is improving slowly (144 → 139 days).
A33: Days Inventory Outstanding (DIO) | B33: 365 / Inventory Turnover | C33: =IF('03_RAW_DATA'!C39=0,"n/a",'04_ASSUMPTIONS'!$C$4/('03_RAW_DATA'!C9/'03_RAW_DATA'!C39)) -> n/a | D33: =IF('03_RAW_DATA'!D39=0,"n/a",'04_ASSUMPTIONS'!$C$4/('03_RAW_DATA'!D9/'03_RAW_DATA'!D39)) -> n/a | E33: =IF('03_RAW_DATA'!E39=0,"n/a",'04_ASSUMPTIONS'!$C$4/('03_RAW_DATA'!E9/'03_RAW_DATA'!E39)) -> n/a | G33: Not applicable — no inventory.
A34: Days Payables Outstanding (DPO) | B34: 365 / (COGS / Accounts Payable) | C34: ='04_ASSUMPTIONS'!$C$4/('03_RAW_DATA'!C9/'03_RAW_DATA'!C57) -> 287.06167 | D34: ='04_ASSUMPTIONS'!$C$4/('03_RAW_DATA'!D9/'03_RAW_DATA'!D57) -> 206.83461 | E34: ='04_ASSUMPTIONS'!$C$4/('03_RAW_DATA'!E9/'03_RAW_DATA'!E57) -> 219.58962 | G34: Appears very long (207–287 days) because Elm reports trade payables together with accruals, employee costs and other current liabilities in one line. Pure supplier payment days would be much shorter.

Sheet 06_MODEL
A1: 06 | MODEL — DuPont ROE Decomposition & Cash Conversion Cycle
A3: DUPONT ROE DECOMPOSITION
A4: ROE = Net Profit Margin × Asset Turnover × Equity Multiplier
A5: Component | B5: FY2023 | C5: FY2024 | D5: FY2025 | E5: What It Tells You (1 line)
A6: Net Profit Margin (Net Income / Revenue) | B6: ='03_RAW_DATA'!C27/'03_RAW_DATA'!C8 -> 0.22992732 | C6: ='03_RAW_DATA'!D27/'03_RAW_DATA'!D8 -> 0.24664495 | D6: ='03_RAW_DATA'!E27/'03_RAW_DATA'!E8 -> 0.22085053 | E6: How much profit survives per SAR of revenue — high and stable (~22–25%), dipping in FY2025 on higher interest and costs.
A7: Asset Turnover (Revenue / Total Assets) | B7: ='03_RAW_DATA'!C8/'03_RAW_DATA'!C55 -> 0.72844361 | C7: ='03_RAW_DATA'!D8/'03_RAW_DATA'!D55 -> 0.77525139 | D7: ='03_RAW_DATA'!E8/'03_RAW_DATA'!E55 -> 0.79623907 | E7: How efficiently assets generate revenue — low (<1x) for a cash-rich services firm, but improving every year.
A8: Equity Multiplier (Total Assets / Total Equity) | B8: ='03_RAW_DATA'!C55/'03_RAW_DATA'!C79 -> 2.0270032 | C8: ='03_RAW_DATA'!D55/'03_RAW_DATA'!D79 -> 1.8049522 | D8: ='03_RAW_DATA'!E55/'03_RAW_DATA'!E79 -> 3.2825118 | E8: How much of the asset base is funded by liabilities vs. equity — fell in FY2024, then jumped in FY2025 on the new loan and the SAR 3.1bn equity reduction.
A9: ROE (check: multiply the 3 components) | B9: =B6*B7*B8 -> 0.33950092 | C9: =C6*C7*C8 -> 0.34512823 | D9: =D6*D7*D8 -> 0.57722911 | E9: Should match your ROE in 05_ANALYSIS — the FY2025 jump comes almost entirely from the equity multiplier, not from better margins or efficiency.
A10: ROE per 05_ANALYSIS | B10: ='05_ANALYSIS'!C10 -> 0.33950092 | C10: ='05_ANALYSIS'!D10 -> 0.34512823 | D10: ='05_ANALYSIS'!E10 -> 0.57722911 | E10: Linked from 05_ANALYSIS.
A11: Check: difference (should be 0) | B11: =ROUND(B9-B10,6) -> 0 | C11: =ROUND(C9-C10,6) -> 0 | D11: =ROUND(D9-D10,6) -> 0 | E11: If not zero, find the error before proceeding.
A13: CASH CONVERSION CYCLE (CCC) BRIDGE
A14: CCC = DSO + DIO − DPO. Pull DSO, DIO and DPO from 05_ANALYSIS.
A15: Component | B15: FY2023 | C15: FY2024 | D15: FY2025
A16: Days Sales Outstanding (DSO) | B16: ='05_ANALYSIS'!C32 -> 143.71091 | C16: ='05_ANALYSIS'!D32 -> 142.67391 | D16: ='05_ANALYSIS'!E32 -> 139.07975 | E16: ~140 days to collect from (mainly government) customers — the main drag on cash.
A17: + Days Inventory Outstanding (DIO) | B17: =IF(ISNUMBER('05_ANALYSIS'!C33),'05_ANALYSIS'!C33,0) -> 0 | C17: =IF(ISNUMBER('05_ANALYSIS'!D33),'05_ANALYSIS'!D33,0) -> 0 | D17: =IF(ISNUMBER('05_ANALYSIS'!E33),'05_ANALYSIS'!E33,0) -> 0 | E17: Zero — Elm holds no inventory (05_ANALYSIS shows n/a).
A18: − Days Payables Outstanding (DPO) | B18: ='05_ANALYSIS'!C34 -> 287.06167 | C18: ='05_ANALYSIS'!D34 -> 206.83461 | D18: ='05_ANALYSIS'!E34 -> 219.58962 | E18: Overstated: the payables line includes accruals, employee costs and other current liabilities, not just suppliers.
A19: Cash Conversion Cycle (days) | B19: =B16+B17-B18 -> -143.35076 | C19: =C16+C17-C18 -> -64.160696 | D19: =D16+D17-D18 -> -80.509861 | E19: Negative CCC means Elm collects from customers before it pays its payables/accruals. It moved from −143 days (FY2023) to −64 (FY2024) and −81 (FY2025) — less favourable than FY2023, mainly because DPO fell. The result is flattered by the broad payables line; collections (DSO) remain the real issue.

Sheet 09_EXEC_RECOMMENDATION
A1: 09 | EXECUTIVE RECOMMENDATION — Board Briefing Note
A2: Elm Company (شركة علم) | Prepared for: Independent Non-Executive Director (private briefing, not for management circulation)
A3: Figures in SAR. Sources: 03_RAW_DATA, 05_ANALYSIS, 06_MODEL and the FY2025 audited notes (Notes 5, 18, 29, 33, 35, 37, 40).
A5: Executive Summary (3-5 sentences — what does the director most need to know before the meeting?)
A6: Management's board pack will likely present a record year — revenue up 28% to SAR 9.5bn, net income up 14% to SAR 2.1bn and ROE jumping to 58% — and the core digital business genuinely is strong and cash-generative. But FY2025 was a transformational year that the headline numbers disguise: Elm paid SAR 3.39bn to its controlling shareholder (PIF) for Thiqah, a business with only SAR 264m of book net assets, funded it with the company's first-ever bank loan (SAR 1.9bn), and charged SAR 3.12bn straight to retained earnings. That accounting — not better performance — is what drives the ROE spike; on a like-for-like equity base ROE actually fell from 34.5% to about 31%, margins slipped as the lower-margin BPO segment grew, and net cash fell 41% from SAR 3.7bn to SAR 2.2bn. Meanwhile SAR 1.3bn of receivables are more than a year overdue and DSO sits near 140 days — collections, not borrowing, are the largest untapped source of cash. The director should go in focused on whether the Thiqah price is being earned, why its net assets had to be written down by SAR 311m after the interim accounts, and what discipline governs further debt-funded deals.
A8: What Management's Board Pack Likely Understates (top 3-5 findings, plain language)
A9: 1. ROE of 57.7% is an accounting effect, not a performance improvement. Because Thiqah was bought from a party under common control (PIF), the SAR 3.12bn excess over book value was charged to retained earnings instead of being recorded as goodwill. Equity fell from SAR 5.3bn to 3.6bn, and the DuPont model shows the entire ROE jump comes from the equity multiplier (1.81x → 3.28x). Net margin (24.7% → 22.1%) and ROA (19.1% → 17.6%) both declined. Adding the SAR 3.12bn back, ROE would be about 31% — below FY2024's 34.5%.
A10: 2. Profitability is quietly diluting as the business mix shifts toward lower-margin BPO. Gross margin fell from 40.9% to 38.9% and EBIT margin from 23.0% to 21.5%. The core Digital segment held its ~47% gross margin, but Business Process Outsourcing (which grew 43%, largely through Thiqah) saw gross margin fall from 24.0% to 18.6%. Net income is also flattered by a ~SAR 69m reversal of prior-year zakat provisions (Note 33); excluding it, net margin is about 21.4%. Part of the 28% revenue growth is acquired, not organic — the pack should split the two.
A11: 3. The balance sheet has moved from a large net-cash position to a leveraged one in a single year. Elm was debt-free in FY2023–FY2024. It now carries a SAR 1.97bn loan (repayable in five annual instalments from April 2026), debt-to-equity is 0.54x and liabilities fund 70% of assets (from 45%). Cash plus murabaha deposits still look healthy at SAR 4.1bn, but net of the loan they are SAR 2.2bn versus SAR 3.7bn a year earlier (−41%). Interest coverage remains safe at 19x but has fallen from 230x in two years, and the cash ratio (incl. deposits) dropped from 1.08x to 0.74x. SAR 2.4bn of capital commitments and ~SAR 660m of annual dividends compete for the same cash.
A12: 4. A large, quantifiable cash source sits in overdue receivables. Net receivables are SAR 3.6bn (DSO ≈139 days — roughly 2.5x a normal 50–55 day benchmark). Of the SAR 4.35bn gross balance, SAR 1.31bn (30%) is more than 365 days overdue — SAR 710m government and SAR 597m commercial — and the credit-loss allowance has risen to SAR 748m. Every 10 days of DSO is worth ~SAR 260m of cash; cutting DSO to 120 days would release ~SAR 0.5bn, and to 90 days ~SAR 1.3bn — comparable to two-thirds of the new loan. Unbilled contract assets also jumped 83% to SAR 1.17bn.
A13: 5. The Thiqah acquisition raises related-party and control questions the pack may gloss over. The price (SAR 3.39bn) was about 12.8x the book value of net assets acquired, paid to the controlling shareholder. After the interim accounts were published, a post-completion review cut Thiqah's acquired net assets from SAR 575m to SAR 264m (−SAR 311m, Note 40-a), mainly in intangibles, receivables, contract assets and CWIP. That suggests the pre-deal due diligence missed material issues — and the valuation paid may rest on assumptions the Board has not yet been able to test against post-acquisition results.
A15: Your Top 5 Questions for Management (expanded list, with the 'why this matters' for each)
... A23: Accept the FY2025 results, but do not approve any further debt-funded acquisition, related-party transaction or dividend increase until management answers the questions above. Specifically request: (1) a Thiqah post-acquisition performance review against the original business case, reported to the Board quarterly; (2) an independent review of the due-diligence process that led to the SAR 311m net-asset revision; (3) a receivables recovery plan with a DSO target (e.g. ≤120 days within 12 months); and (4) a Board-approved capital-structure and leverage policy before the next major capital decision.
